<?xml version="1.0" ?>
<robot name="AMR_Platform">
  <material name="blue">
    <color rgba="0 0 0.8 1"/>
  </material>
  <material name="black">
    <color rgba="0 0 0 1"/>
  </material>
  <material name="white">
    <color rgba="1 1 1 1"/>
  </material>
  <link name="base_link">
  </link>
  <link name="main_body">
    <visual>
      <origin rpy="1.5707963267949 0 1.5707963267949" xyz="0 0 0"/>
      <geometry>
        <mesh filename="package://amr_visualisation/meshes/LD90.obj"/>
      </geometry>
      <material name="white"/>
    </visual>
    <collision>
      <origin rpy="1.5707963267949 0 1.5707963267949" xyz="0 0 0"/>
      <geometry>
        <mesh filename="package://amr_visualisation/meshes/LD90.obj"/>
      </geometry>
    </collision>
    <inertial>
      <mass value="4.07"/>
      <inertia ixx="0.426" ixy="0.0" ixz="0.0" iyy="0.496" iyz="0.0" izz="0.91"/>
    </inertial>
  </link>
  <joint name="main_body_to_base" type="fixed">
    <parent link="base_link"/>
    <child link="main_body"/>
    <origin xyz="0 0 0"/>
  </joint>

  <joint name="chassis_connector" type="fixed">
    <axis rpy="0 0 1.57" xyz="0 0 0.5"/>
    <parent link="main_body"/>
    <child link="chassis"/>
  </joint>

  <link name="chassis">
    <visual>
      <origin rpy="1.5707963267949 0 1.5707963267949" xyz="-0.525 -0.294 -0.214"/>
      <geometry>
        <mesh filename="package://omron_moma/chassis.obj"/>
      </geometry>
    </visual>
    <collision>
      <origin rpy="1.5707963267949 0 1.5707963267949" xyz="-0.525 -0.294 -0.214"/>
      <geometry>
        <mesh filename="package://omron_moma/chassis.stl"/>
      </geometry>
    </collision>
  </link>

  <joint name="tm_connector" type="fixed">
    <parent link="chassis"/>
    <child link="tm_base"/>
    <origin xyz="0.14 0 0.8405" rpy="0 0 0"/>
  </joint>

  <link name="tm_base">
    <visual>
      <geometry>
        <mesh filename="package://tmr_description/meshes/tm5-900/visual/tm5_base.obj"/>
      </geometry>
    </visual>
    <collision>
      <geometry>
        <mesh filename="package://tmr_description/meshes/tm5-900/collision/tm5_base_c.stl"/>
      </geometry>
    </collision>
  </link>

  <joint name="joint_1" type="revolute">
    <parent link="tm_base"/>
    <child link="link_1"/>
    <origin xyz="0 0 0.1452" rpy="0 0 0"/>
    <axis xyz="0 0 1"/>
    <limit effort="100.0" lower="-3.14" upper="3.14" velocity="1.0"/>
  </joint>

  <link name="link_1">
    <visual>
      <geometry>
        <mesh filename="package://tmr_description/meshes/tm5-900/visual/tmr_400w_01.obj"/>
      </geometry>
    </visual>
    <collision>
      <geometry>
        <mesh filename="package://tmr_description/meshes/tm5-900/collision/tmr_400w_01_c.stl"/>
      </geometry>
    </collision>
  </link>

  <joint name="joint_2" type="revolute">
    <parent link="link_1"/>
    <child link="link_2"/>
    <origin xyz="0 0 0" rpy="-1.570796327 -1.570796327 0"/>
    <axis xyz="0 0 1"/>
    <limit effort="100.0" lower="-3.14" upper="3.14" velocity="1.0"/>
  </joint>

  <link name="link_2">
    <visual>
      <geometry>
        <mesh filename="package://tmr_description/meshes/tm5-900/visual/tm5-900_arm1.obj"/>
      </geometry>
    </visual>
    <collision>
      <geometry>
        <mesh filename="package://tmr_description/meshes/tm5-900/collision/tm5-900_arm1_c.stl"/>
      </geometry>
    </collision>
  </link>

  <joint name="joint_3" type="revolute">
    <parent link="link_2"/>
    <child link="link_3"/>
    <origin  xyz="0.429 0 0" rpy="0 0 0"/>
    <axis xyz="0 0 1"/>
    <limit effort="100.0" lower="-3.14" upper="3.14" velocity="1.0"/>
  </joint>

  <link name="link_3">
    <visual>
      <geometry>
        <mesh filename="package://tmr_description/meshes/tm5-900/visual/tm5-900_arm2.obj"/>
      </geometry>
    </visual>
    <collision>
      <geometry>
        <mesh filename="package://tmr_description/meshes/tm5-900/collision/tm5-900_arm2_c.stl"/>
      </geometry>
    </collision>
  </link>

  <joint name="joint_4" type="revolute">
    <parent link="link_3"/>
    <child link="link_4"/>
    <origin xyz="0.4115 0 -0.1223" rpy="0 0 1.570796327"/>
    <axis xyz="0 0 1"/>
    <limit effort="10.0" lower="-3.14" upper="3.14" velocity="1.0"/>
  </joint>

  <link name="link_4">
    <visual>
      <geometry>
        <mesh filename="package://tmr_description/meshes/tm5-900/visual/tmr_100w_01.obj"/>
      </geometry>
    </visual>
    <collision>
      <geometry>
        <mesh filename="package://tmr_description/meshes/tm5-900/collision/tmr_100w_01_c.stl"/>
      </geometry>
    </collision>
  </link>

  <joint name="joint_5" type="revolute">
    <parent link="link_4"/>
    <child link="link_5"/>
    <origin xyz="0 -0.106 0" rpy="1.570796327 0 0"/>
    <axis xyz="0 0 1"/>
    <limit effort="10.0" lower="-3.14" upper="3.14" velocity="1.0"/>
  </joint>

  <link name="link_5">
    <visual>
      <geometry>
        <mesh filename="package://tmr_description/meshes/tm5-900/visual/tmr_100w_02.obj"/>
      </geometry>
    </visual>
    <collision>
      <geometry>
        <mesh filename="package://tmr_description/meshes/tm5-900/collision/tmr_100w_02_c.stl"/>
      </geometry>
    </collision>
  </link>

  <joint name="joint_6" type="revolute">
    <parent link="link_5"/>
    <child link="link_6"/>
    <origin xyz="0 -0.11315 0" rpy="1.570796327 0 0"/>
    <axis xyz="0 0 1"/>
    <limit effort="10.0" lower="-3.14" upper="3.14" velocity="1.0"/>
  </joint>

  <link name="link_6">
    <visual>
      <geometry>
        <mesh filename="package://tmr_description/meshes/tm5-900/visual/tmr_ee.obj"/>
      </geometry>
    </visual>
    <collision>
      <geometry>
        <mesh filename="package://tmr_description/meshes/tm5-900/collision/tmr_ee_c.stl"/>
      </geometry>
    </collision>
  </link>

  <joint name="joint_EOAT" type="fixed">
    <parent link="link_6"/>
    <child link="EOAT"/>
    <origin xyz="0 0 0" rpy="0 0 0"/>
    <!-- <axis xyz="0 0 0"/> -->
  </joint>

  <link name="EOAT">
    <visual>
      <geometry>
        <mesh filename="package://robotiq_description/meshes/visual/2f_85/robotiq_base.dae"/>
      </geometry>
    </visual>
    <collision>
      <geometry>
        <mesh filename="package://robotiq_description/meshes/collision/2f_85/robotiq_base.stl"/>
      </geometry>
    </collision>
    <inertial>
      <origin xyz="0.0 2.274e-05 0.03232288" rpy="0 0 0" />
      <mass value="6.6320197e-01" />
      <inertia ixx="5.1617816e-04" iyy="5.8802208e-04" izz="3.9462776e-04" ixy="2.936e-8" ixz="0.0" iyz="-3.2296e-7" />
    </inertial>
  </link>

  <link name="flange"/>
  <joint name="flange_fixed_joint" type="fixed">
    <parent link="link_6"/>
    <child link="flange"/>
    <origin xyz="0 0 0" rpy="0 0 0"/>
  </joint>

  <joint name="gripper_robotiq_85_left_knuckle_joint" type="fixed">
    <parent link="EOAT" />
    <child link="gripper_robotiq_85_left_knuckle_link" />
    <axis xyz="0 -1 0" />
    <origin xyz="0.03060114 0.0 0.05490452" rpy="0 0 0" />
    <!-- <limit lower="0.0" upper="0.8" velocity="0.5" effort="50" /> -->
  </joint>

  <link name="gripper_robotiq_85_left_knuckle_link">
    <visual>
      <geometry>
        <mesh filename="package://robotiq_description/meshes/visual/2f_85/left_knuckle.dae" />
      </geometry>
    </visual>
    <collision>
      <geometry>
        <mesh filename="package://robotiq_description/meshes/collision/2f_85/left_knuckle.stl" />
      </geometry>
    </collision>
    <inertial>
      <origin xyz="0.01213197 0.0002 -0.00058647" rpy="0 0 0" />
      <mass value="1.384773208e-02" />
      <inertia ixx="3.5232e-7" iyy="2.31944e-6" izz="2.23136e-6" ixy="0.0" ixz="1.1744e-7" iyz="0" />
    </inertial>
  </link>

</robot>

  <joint name="gripper_robotiq_85_right_knuckle_joint" type="fixed">
    <parent link="gripper_robotiq_85_base_link" />
    <child link="gripper_robotiq_85_right_knuckle_link" />
    <axis xyz="0 -1 0" />
    <origin xyz="-0.03060114 0.0 0.05490452" rpy="0 0 0" />
    <!-- <limit lower="-0.8" upper="0.0" velocity="0.5" effort="50" /> -->
    <!-- <mimic joint="gripper_robotiq_85_left_knuckle_joint" multiplier="-1" /> -->
  </joint>

  <link name="gripper_robotiq_85_right_knuckle_link">
    <visual>
      <geometry>
        <mesh filename="package://robotiq_description/meshes/visual/2f_85/right_knuckle.dae" />
      </geometry>
    </visual>
    <collision>
      <geometry>
        <mesh filename="package://robotiq_description/meshes/collision/2f_85/right_knuckle.stl" />
      </geometry>
    </collision>
    <inertial>
      <origin xyz="-0.01213197 0.0002 -0.00058647" rpy="0 0 0" />
      <mass value="1.384773208e-02" />
      <inertia ixx="3.5232e-7" iyy="2.31944e-6" izz="2.23136e-6" ixy="0.0" ixz="-1.1744e-7" iyz="0.0" />
    </inertial>
  </link>

  <joint name="gripper_robotiq_85_left_finger_joint" type="fixed">
    <parent link="gripper_robotiq_85_left_knuckle_link" />
    <child link="gripper_robotiq_85_left_finger_link" />
    <origin xyz="0.03152616 0.0 -0.00376347" rpy="0 0 0" />
  </joint>

  <link name="gripper_robotiq_85_left_finger_link">
    <visual>
      <geometry>
        <mesh filename="package://robotiq_description/meshes/visual/2f_85/left_finger.dae" />
      </geometry>
    </visual>
    <collision>
      <geometry>
        <mesh filename="package://robotiq_description/meshes/collision/2f_85/left_finger.stl" />
      </geometry>
    </collision>
    <inertial>
      <origin xyz="0.00346899 -0.00079447 0.01867121" rpy="0 0 0" />
      <mass value="4.260376752e-02" />
      <inertia ixx="1.385792000000000e-05" iyy="1.183208e-05" izz="5.19672e-06" ixy="0.0" ixz="-2.17264e-06" iyz="0.0" />
    </inertial>
  </link>

  <joint name="gripper_robotiq_85_right_finger_joint" type="fixed">
    <parent link="gripper_robotiq_85_right_knuckle_link" />
    <child link="gripper_robotiq_85_right_finger_link" />
    <origin xyz="-0.03152616 0.0 -0.00376347" rpy="0 0 0" />
  </joint>

  <link name="gripper_robotiq_85_right_finger_link">
    <visual>
      <geometry>
        <mesh filename="package://robotiq_description/meshes/visual/2f_85/right_finger.dae" />
      </geometry>
    </visual>
    <collision>
      <geometry>
        <mesh filename="package://robotiq_description/meshes/collision/2f_85/right_finger.stl" />
      </geometry>
    </collision>
    <inertial>
      <origin xyz="-0.00346899 -5.53e-06 0.01867121" rpy="0 0 0" />
      <mass value="4.260376752000000e-02" />
      <inertia ixx="1.385792e-05" iyy="1.183208e-05" izz="5.19672e-06" ixy="0.0" ixz="2.17264e-06" iyz="0.0" />
    </inertial>
  </link>

  <joint name="gripper_robotiq_85_left_inner_knuckle_joint" type="fixed">
    <parent link="gripper_robotiq_85_base_link" />
    <child link="gripper_robotiq_85_left_inner_knuckle_link" />
    <axis xyz="0 -1 0" />
    <origin xyz="0.0127 0.0 0.06142" rpy="0 0 0" />
    <!-- <mimic joint="gripper_robotiq_85_left_knuckle_joint" /> -->
  </joint>

  <link name="gripper_robotiq_85_left_inner_knuckle_link">
    <visual>
      <geometry>
        <mesh filename="package://robotiq_description/meshes/visual/2f_85/left_inner_knuckle.dae" />
      </geometry>
    </visual>
    <collision>
      <geometry>
        <mesh filename="package://robotiq_description/meshes/collision/2f_85/left_inner_knuckle.stl" />
      </geometry>
    </collision>
    <inertial>
      <origin xyz="0.01897699 0.00015001 0.02247101" rpy="0 0 0" />
      <mass value="2.969376448e-02" />
      <inertia ixx="9.57136e-06" iyy="8.69056e-06" izz="8.19144e-06" ixy="0.0" ixz="-3.93424e-06" iyz="0.0" />
    </inertial>
  </link>

  <joint name="gripper_robotiq_85_right_inner_knuckle_joint" type="fixed">
    <parent link="gripper_robotiq_85_base_link" />
    <child link="gripper_robotiq_85_right_inner_knuckle_link" />
    <axis xyz="0 -1 0" />
    <origin xyz="-0.0127 0.0 0.06142" rpy="0 0 0" />
    <!-- <mimic joint="gripper_robotiq_85_left_knuckle_joint" multiplier="-1" /> -->
  </joint>

  <link name="gripper_robotiq_85_right_inner_knuckle_link">
    <visual>
      <geometry>
        <mesh filename="package://robotiq_description/meshes/visual/2f_85/right_inner_knuckle.dae" />
      </geometry>
    </visual>
    <collision>
      <geometry>
        <mesh filename="package://robotiq_description/meshes/collision/2f_85/right_inner_knuckle.stl" />
      </geometry>
    </collision>
    <inertial>
      <origin xyz="-0.01926824 5.001e-05 0.02222178" rpy="0 0 0" />
      <mass value="2.969376448e-02" />
      <inertia ixx="9.42456e-06" iyy="8.69056e-06" izz="8.33824e-06" ixy="0.0" ixz="3.9636e-06" iyz="0.0" />
    </inertial>
  </link>

  <joint name="gripper_robotiq_85_left_finger_tip_joint" type="fixed">
    <parent link="gripper_robotiq_85_left_finger_link" />
    <child link="gripper_robotiq_85_left_finger_tip_link" />
    <axis xyz="0 -1 0" />
    <origin xyz="0.00563134 0.0 0.04718515" rpy="0 0 0" />
    <!-- <mimic joint="gripper_robotiq_85_left_knuckle_joint" multiplier="-1" /> -->
  </joint>

  <link name="gripper_robotiq_85_left_finger_tip_link">
    <visual>
      <geometry>
        <mesh filename="package://robotiq_description/meshes/visual/2f_85/left_finger_tip.dae" />
      </geometry>
    </visual>
    <collision>
      <geometry>
        <mesh filename="package://robotiq_description/meshes/collision/2f_85/left_finger_tip.stl" />
      </geometry>
      <surface>
        <friction>
        <ode>
          <mu1>100000.0</mu1>
          <mu2>100000.0</mu2>
        </ode>
        </friction>
        <contact>
        <ode>
          <kp>1e+5</kp>
          <kd>1</kd>
          <soft_cfm>0</soft_cfm>
          <soft_erp>0.2</soft_erp>
          <minDepth>0.002</minDepth>
          <maxVel>0</maxVel>
        </ode>
        </contact>
      </surface>
    </collision>
    <inertial>
        <origin xyz="-0.01456706 -0.0008 0.01649701" rpy="0 0 0" />
        <mass value="4.268588744e-02" />
        <inertia ixx="1.048152e-05" iyy="1.197888e-05" izz="4.22784e-06" ixy="0.0" ixz="3.5232e-6" iyz="0.0" />
    </inertial>
  </link>

  <joint name="gripper_robotiq_85_right_finger_tip_joint" type="fixed">
    <parent link="gripper_robotiq_85_right_finger_link" />
    <child link="gripper_robotiq_85_right_finger_tip_link" />
    <axis xyz="0 -1 0" />
    <origin xyz="-0.00563134 0.0 0.04718515" rpy="0 0 0" />
    <!-- <mimic joint="gripper_robotiq_85_left_knuckle_joint" /> -->
  </joint>

  <link name="gripper_robotiq_85_right_finger_tip_link">
    <visual>
      <geometry>
        <mesh filename="package://robotiq_description/meshes/visual/2f_85/right_finger_tip.dae" />
      </geometry>
    </visual>
    <collision>
      <geometry>
          <mesh filename="package://robotiq_description/meshes/collision/2f_85/right_finger_tip.stl" />
      </geometry>
      <surface>
        <friction>
        <ode>
          <mu1>100000.0</mu1>
          <mu2>100000.0</mu2>
        </ode>
        </friction>
        <contact>
        <ode>
          <kp>1e+5</kp>
          <kd>1</kd>
          <soft_cfm>0</soft_cfm>
          <soft_erp>0.2</soft_erp>
          <minDepth>0.002</minDepth>
          <maxVel>0</maxVel>
        </ode>
        </contact>
      </surface>
    </collision>
    <inertial>
      <origin xyz="0.01456706 5e-05 0.01649701" rpy="0 0 0" />
      <mass value="4.268588744e-02" />
      <inertia ixx="1.048152e-05" iyy="1.197888e-05" izz="4.22784e-06" ixy="0.0" ixz="-3.5232e-06" iyz="0.0" />
    </inertial>
  </link> -->

  <link name="flange"/>
  <joint name="flange_fixed_joint" type="fixed">
    <parent link="link_6"/>
    <child link="flange"/>
    <origin xyz="0 0 0" rpy="0 0 0"/>
  </joint>
</robot>
