<?xml version="1.0"?>
<robot xmlns:xacro="http://www.ros.org/wiki/xacro" name="AMR_Platform">

  <!-- Gripper parameters -->
  <xacro:arg name="use_fake_hardware" default="false"/>
  <xacro:arg name="com_port" default="/dev/ttyUSB0"/>

  <!-- Gripper macro include -->
  <xacro:include filename="$(find robotiq_description)/urdf/robotiq_2f_85_macro.urdf.xacro"/>

  <!-- Define materials -->
  <material name="blue">
    <color rgba="0 0 0.8 1"/>
  </material>
  <material name="black">
    <color rgba="0 0 0 1"/>
  </material>
  <material name="white">
    <color rgba="1 1 1 1"/>
  </material>

  <!-- Base and main body -->
  <link name="base_link"/>
  <link name="main_body">
    <visual>
      <origin rpy="1.5707963267949 0 1.5707963267949" xyz="0 0 0"/>
      <geometry>
        <mesh filename="package://amr_visualisation/meshes/LD90.obj"/>
      </geometry>
      <material name="white"/>
    </visual>
    <collision>
      <origin rpy="1.5707963267949 0 1.5707963267949" xyz="0 0 0"/>
      <geometry>
        <mesh filename="package://amr_visualisation/meshes/LD90.obj"/>
      </geometry>
    </collision>
    <inertial>
      <mass value="4.07"/>
      <inertia ixx="0.426" ixy="0.0" ixz="0.0" iyy="0.496" iyz="0.0" izz="0.91"/>
    </inertial>
  </link>

  <joint name="main_body_to_base" type="fixed">
    <parent link="base_link"/>
    <child link="main_body"/>
    <origin xyz="0 0 0"/>
  </joint>

  <joint name="chassis_connector" type="fixed">
    <axis rpy="0 0 1.57" xyz="0 0 0.5"/>
    <parent link="main_body"/>
    <child link="chassis"/>
  </joint>

  <link name="chassis">
    <visual>
      <origin rpy="1.5707963267949 0 1.5707963267949" xyz="-0.525 -0.294 -0.214"/>
      <geometry>
        <mesh filename="package://omron_moma/chassis.obj"/>
      </geometry>
    </visual>
    <collision>
      <origin rpy="1.5707963267949 0 1.5707963267949" xyz="-0.525 -0.294 -0.214"/>
      <geometry>
        <mesh filename="package://omron_moma/chassis.stl"/>
      </geometry>
    </collision>
  </link>

  <!-- TM robot arm chain -->
  <joint name="tm_connector" type="fixed">
    <parent link="chassis"/>
    <child link="tm_base"/>
    <origin xyz="0.14 0 0.8405" rpy="0 0 0"/>
  </joint>

  <link name="tm_base">
    <visual>
      <geometry>
        <mesh filename="package://tmr_description/meshes/tm5-900/visual/tm5_base.obj"/>
      </geometry>
    </visual>
    <collision>
      <geometry>
        <mesh filename="package://tmr_description/meshes/tm5-900/collision/tm5_base_c.stl"/>
      </geometry>
    </collision>
  </link>

  <joint name="joint_1" type="revolute">
    <parent link="tm_base"/>
    <child link="link_1"/>
    <origin xyz="0 0 0.1452" rpy="0 0 0"/>
    <axis xyz="0 0 1"/>
    <limit effort="100.0" lower="-3.14" upper="3.14" velocity="1.0"/>
  </joint>

  <link name="link_1">
    <visual>
      <geometry>
        <mesh filename="package://tmr_description/meshes/tm5-900/visual/tmr_400w_01.obj"/>
      </geometry>
    </visual>
    <collision>
      <geometry>
        <mesh filename="package://tmr_description/meshes/tm5-900/collision/tmr_400w_01_c.stl"/>
      </geometry>
    </collision>
  </link>

  <joint name="joint_2" type="revolute">
    <parent link="link_1"/>
    <child link="link_2"/>
    <origin xyz="0 0 0" rpy="-1.570796327 -1.570796327 0"/>
    <axis xyz="0 0 1"/>
    <limit effort="100.0" lower="-3.14" upper="3.14" velocity="1.0"/>
  </joint>

  <link name="link_2">
    <visual>
      <geometry>
        <mesh filename="package://tmr_description/meshes/tm5-900/visual/tm5-900_arm1.obj"/>
      </geometry>
    </visual>
    <collision>
      <geometry>
        <mesh filename="package://tmr_description/meshes/tm5-900/collision/tm5-900_arm1_c.stl"/>
      </geometry>
    </collision>
  </link>

  <joint name="joint_3" type="revolute">
    <parent link="link_2"/>
    <child link="link_3"/>
    <origin xyz="0.429 0 0" rpy="0 0 0"/>
    <axis xyz="0 0 1"/>
    <limit effort="100.0" lower="-3.14" upper="3.14" velocity="1.0"/>
  </joint>

  <link name="link_3">
    <visual>
      <geometry>
        <mesh filename="package://tmr_description/meshes/tm5-900/visual/tm5-900_arm2.obj"/>
      </geometry>
    </visual>
    <collision>
      <geometry>
        <mesh filename="package://tmr_description/meshes/tm5-900/collision/tm5-900_arm2_c.stl"/>
      </geometry>
    </collision>
  </link>

  <joint name="joint_4" type="revolute">
    <parent link="link_3"/>
    <child link="link_4"/>
    <origin xyz="0.4115 0 -0.1223" rpy="0 0 1.570796327"/>
    <axis xyz="0 0 1"/>
    <limit effort="10.0" lower="-3.14" upper="3.14" velocity="1.0"/>
  </joint>

  <link name="link_4">
    <visual>
      <geometry>
        <mesh filename="package://tmr_description/meshes/tm5-900/visual/tmr_100w_01.obj"/>
      </geometry>
    </visual>
    <collision>
      <geometry>
        <mesh filename="package://tmr_description/meshes/tm5-900/collision/tmr_100w_01_c.stl"/>
      </geometry>
    </collision>
  </link>

  <joint name="joint_5" type="revolute">
    <parent link="link_4"/>
    <child link="link_5"/>
    <origin xyz="0 -0.106 0" rpy="1.570796327 0 0"/>
    <axis xyz="0 0 1"/>
    <limit effort="10.0" lower="-3.14" upper="3.14" velocity="1.0"/>
  </joint>

  <link name="link_5">
    <visual>
      <geometry>
        <mesh filename="package://tmr_description/meshes/tm5-900/visual/tmr_100w_02.obj"/>
      </geometry>
    </visual>
    <collision>
      <geometry>
        <mesh filename="package://tmr_description/meshes/tm5-900/collision/tmr_100w_02_c.stl"/>
      </geometry>
    </collision>
  </link>

  <joint name="joint_6" type="revolute">
    <parent link="link_5"/>
    <child link="link_6"/>
    <origin xyz="0 -0.11315 0" rpy="1.570796327 0 0"/>
    <axis xyz="0 0 1"/>
    <limit effort="10.0" lower="-3.14" upper="3.14" velocity="1.0"/>
  </joint>

  <link name="link_6">
    <visual>
      <geometry>
        <mesh filename="package://tmr_description/meshes/tm5-900/visual/tmr_ee.obj"/>
      </geometry>
    </visual>
    <collision>
      <geometry>
        <mesh filename="package://tmr_description/meshes/tm5-900/collision/tmr_ee_c.stl"/>
      </geometry>
    </collision>
  </link>

  <!-- Flange link -->
  <link name="flange"/>
  <joint name="flange_fixed_joint" type="fixed">
    <parent link="link_6"/>
    <child link="flange"/>
    <origin xyz="0 0 0" rpy="0 0 0"/>
  </joint>

  <!-- NEW Gripper integration -->
  <xacro:robotiq_gripper
      name="RobotiqGripperHardwareInterface"
      prefix="gripper_"
      parent="flange"
      use_fake_hardware="$(arg use_fake_hardware)"
      com_port="$(arg com_port)">
    <origin xyz="0 0 0.15" rpy="0 0 0"/>
  </xacro:robotiq_gripper>

</robot>
